Check started:


Critical Failure:
Error -- Unexpected Exception:
This is bad

Exception thrown during last check
Last Recorded Message:

Tests/Tests/TestFramework/TestRunnerTest.cpp, Line 45
Throw during check

[sequoia::testing::(anonymous namespace)::foo]
