
Running tests...

Foo:
[0 (0)ms]
	Standard Top Level Checks:                 2;  Failures:  0  [Deep checks: 1]

******  Critical Failures:  1  ******


	Error -- Unexpected Exception:
	Throw after check

	Exception thrown after check completed
	Last Recorded Message:

	Tests/TestFramework/TestRunnerTest.cpp, Line 31

	[int]

	=======================================


-----------Grand Totals-----------
[1 (0)ms]
	Standard Top Level Checks:                 2;  Failures:  0  [Deep checks: 1]
	Standard Performance Checks:               0;  Failures:  0
	False Negative Checks:                     0;  Failures:  0
	False Negative Performance Checks:         0;  Failures:  0
	False Positive Checks:                     0;  Failures:  0
	False Positive Performance Checks:         0;  Failures:  0

******  Critical Failures:  1  ******

