Unit Test
Standard Top Level Checks:                 2;  Failures:  0  [Deep checks: 0]

******  Critical Failures:  1  ******


	Error -- Unexpected Exception:
	This is bad

	Exception thrown during last check
	Last Recorded Message:

	Tests/TestFramework/TestRunnerTest.cpp, Line 36
	Throw during check

	[sequoia::testing::(anonymous namespace)::foo]

	=======================================

